<?xml version="1.0" encoding="utf-8" ?>
<!-- This URDF was automatically created by SolidWorks to URDF Exporter! Originally created by Stephen Brawner (brawner@gmail.com) 
     Commit Version: 1.6.0-1-g15f4949  Build Version: 1.6.7594.29634
     For more information, please see http://wiki.ros.org/sw_urdf_exporter -->
<robot name="asd">
    <link name="base_link">
        <inertial>
            <origin xyz="-7.8444E-17 0.060601 1.6862E-17" rpy="0 0 0" />
            <mass value="0.098899" />
            <inertia ixx="0.0002369" ixy="-6.012E-20" ixz="-5.8937E-20" iyy="0.00027185" iyz="-4.5513E-20" izz="0.0002369" />
        </inertial>
        <visual>
            <origin xyz="0 0 0" rpy="0 0 0" />
            <geometry>
                <mesh filename="package://asd/meshes/base_link.STL" />
            </geometry>
            <material name="">
                <color rgba="1 1 1 1" />
            </material>
        </visual>
        <collision>
            <origin xyz="0 0 0" rpy="0 0 0" />
            <geometry>
                <mesh filename="package://asd/meshes/base_link.STL" />
            </geometry>
        </collision>
    </link>
    <link name="link1">
        <inertial>
            <origin xyz="0.00096508 0.020457 -0.011948" rpy="0 0 0" />
            <mass value="0.14525" />
            <inertia ixx="8.8367E-05" ixy="-1.1727E-05" ixz="1.0311E-05" iyy="0.00011111" iyz="1.9409E-05" izz="9.9992E-05" />
        </inertial>
        <visual>
            <origin xyz="0 0 0" rpy="0 0 0" />
            <geometry>
                <mesh filename="package://asd/meshes/link1.STL" />
            </geometry>
            <material name="">
                <color rgba="1 1 1 1" />
            </material>
        </visual>
        <collision>
            <origin xyz="0 0 0" rpy="0 0 0" />
            <geometry>
                <mesh filename="package://asd/meshes/link1.STL" />
            </geometry>
        </collision>
    </link>
    <joint name="joint1" type="continuous">
        <origin xyz="0 0 0.098" rpy="1.5708 0 2.963" />
        <parent link="base_link" />
        <child link="link1" />
        <axis xyz="0 -1 0" />
        <limit lower="-3.14" upper="3.14" effort="100" velocity="3" />
    </joint>
    <link name="link2">
        <inertial>
            <origin xyz="1.1889E-08 -0.053455 -0.013438" rpy="0 0 0" />
            <mass value="0.50727" />
            <inertia ixx="0.0016732" ixy="9.6555E-12" ixz="-2.2964E-10" iyy="0.0002819" iyz="-1.4798E-05" izz="0.0017533" />
        </inertial>
        <visual>
            <origin xyz="0 0 0" rpy="0 0 0" />
            <geometry>
                <mesh filename="package://asd/meshes/link2.STL" />
            </geometry>
            <material name="">
                <color rgba="1 1 1 1" />
            </material>
        </visual>
        <collision>
            <origin xyz="0 0 0" rpy="0 0 0" />
            <geometry>
                <mesh filename="package://asd/meshes/link2.STL" />
            </geometry>
        </collision>
    </link>
    <joint name="joint2" type="continuous">
        <origin xyz="0.025573 0.057 0" rpy="-3.1416 0 0.83504" />
        <parent link="link1" />
        <child link="link2" />
        <axis xyz="0 0 -1" />
        <limit lower="-3.14" upper="3.14" effort="100" velocity="3" />
    </joint>
    <link name="link3">
        <inertial>
            <origin xyz="-0.011686 0.014271 0.0061667" rpy="0 0 0" />
            <mass value="0.21341" />
            <inertia ixx="9.6225E-05" ixy="1.2826E-05" ixz="-7.4568E-06" iyy="8.8608E-05" iyz="1.9483E-05" izz="8.8243E-05" />
        </inertial>
        <visual>
            <origin xyz="0 0 0" rpy="0 0 0" />
            <geometry>
                <mesh filename="package://asd/meshes/link3.STL" />
            </geometry>
            <material name="">
                <color rgba="1 1 1 1" />
            </material>
        </visual>
        <collision>
            <origin xyz="0 0 0" rpy="0 0 0" />
            <geometry>
                <mesh filename="package://asd/meshes/link3.STL" />
            </geometry>
        </collision>
    </link>
    <joint name="joint3" type="continuous">
        <origin xyz="0 -0.14 0" rpy="3.1416 0 0.68226" />
        <parent link="link2" />
        <child link="link3" />
        <axis xyz="0 0 -1" />
        <limit lower="-3.14" upper="3.14" effort="100" velocity="3" />
    </joint>
    <link name="link4">
        <inertial>
            <origin xyz="0.0027469 7.6295E-06 0.029726" rpy="0 0 0" />
            <mass value="0.12281" />
            <inertia ixx="0.00011827" ixy="-1.3845E-08" ixz="-1.1866E-05" iyy="0.00012545" iyz="-2.1726E-07" izz="2.4813E-05" />
        </inertial>
        <visual>
            <origin xyz="0 0 0" rpy="0 0 0" />
            <geometry>
                <mesh filename="package://asd/meshes/link4.STL" />
            </geometry>
            <material name="">
                <color rgba="1 1 1 1" />
            </material>
        </visual>
        <collision>
            <origin xyz="0 0 0" rpy="0 0 0" />
            <geometry>
                <mesh filename="package://asd/meshes/link4.STL" />
            </geometry>
        </collision>
    </link>
    <joint name="joint4" type="continuous">
        <origin xyz="0 0.0535 0.007" rpy="-1.5708 1.5621 -1.5708" />
        <parent link="link3" />
        <child link="link4" />
        <axis xyz="0 0 1" />
        <limit lower="-3.14" upper="3.14" effort="100" velocity="3" />
    </joint>
    <link name="link5">
        <inertial>
            <origin xyz="2.4993E-05 -0.024284 0.0036916" rpy="0 0 0" />
            <mass value="0.10932" />
            <inertia ixx="7.2868E-05" ixy="-4.5604E-08" ixz="2.9489E-10" iyy="2.4691E-05" iyz="-1.4878E-05" izz="6.5212E-05" />
        </inertial>
        <visual>
            <origin xyz="0 0 0" rpy="0 0 0" />
            <geometry>
                <mesh filename="package://asd/meshes/link5.STL" />
            </geometry>
            <material name="">
                <color rgba="1 1 1 1" />
            </material>
        </visual>
        <collision>
            <origin xyz="0 0 0" rpy="0 0 0" />
            <geometry>
                <mesh filename="package://asd/meshes/link5.STL" />
            </geometry>
        </collision>
    </link>
    <joint name="joint5" type="continuous">
        <origin xyz="0 0 0.112" rpy="-1.5708 -1.0075 1.5708" />
        <parent link="link4" />
        <child link="link5" />
        <axis xyz="0 0 1" />
        <limit lower="-3.14" upper="3.14" effort="100" velocity="3" />
    </joint>
    <link name="link6">
        <inertial>
            <origin xyz="-0.0047212 -0.0048207 0.0465" rpy="0 0 0" />
            <mass value="0.044899" />
            <inertia ixx="5.6932E-06" ixy="5.3782E-10" ixz="1.3272E-14" iyy="5.1194E-06" iyz="1.7708E-13" izz="5.7943E-06" />
        </inertial>
        <visual>
            <origin xyz="0 0 0" rpy="0 0 0" />
            <geometry>
                <mesh filename="package://asd/meshes/link6.STL" />
            </geometry>
            <material name="">
                <color rgba="0.75294 0.75294 0.75294 1" />
            </material>
        </visual>
        <collision>
            <origin xyz="0 0 0" rpy="0 0 0" />
            <geometry>
                <mesh filename="package://asd/meshes/link6.STL" />
            </geometry>
        </collision>
    </link>
    <joint name="joint6" type="fixed">
        <origin xyz="0.0465 -0.073537 -0.0045851" rpy="3.1416 1.5708 -0.055499" />
        <parent link="link5" />
        <child link="link6" />
        <axis xyz="0 0 0" />
        <limit lower="-3.14" upper="3.14" effort="100" velocity="3" />
    </joint>
    <transmission name="trans_joint1">
        <type>transmission_interface/SimpleTransmission</type>
        <joint name="joint1">
            <hardwareInterface>hardware_interface/PositionJointInterface</hardwareInterface>
        </joint>
        <actuator name="joint1_motor">
            <hardwareInterface>hardware_interface/PositionJointInterface</hardwareInterface>
            <mechanicalReduction>1</mechanicalReduction>
        </actuator>
    </transmission>
    <transmission name="trans_joint2">
        <type>transmission_interface/SimpleTransmission</type>
        <joint name="joint2">
            <hardwareInterface>hardware_interface/PositionJointInterface</hardwareInterface>
        </joint>
        <actuator name="joint2_motor">
            <hardwareInterface>hardware_interface/PositionJointInterface</hardwareInterface>
            <mechanicalReduction>1</mechanicalReduction>
        </actuator>
    </transmission>
    <transmission name="trans_joint3">
        <type>transmission_interface/SimpleTransmission</type>
        <joint name="joint3">
            <hardwareInterface>hardware_interface/PositionJointInterface</hardwareInterface>
        </joint>
        <actuator name="joint3_motor">
            <hardwareInterface>hardware_interface/PositionJointInterface</hardwareInterface>
            <mechanicalReduction>1</mechanicalReduction>
        </actuator>
    </transmission>
    <transmission name="trans_joint4">
        <type>transmission_interface/SimpleTransmission</type>
        <joint name="joint4">
            <hardwareInterface>hardware_interface/PositionJointInterface</hardwareInterface>
        </joint>
        <actuator name="joint4_motor">
            <hardwareInterface>hardware_interface/PositionJointInterface</hardwareInterface>
            <mechanicalReduction>1</mechanicalReduction>
        </actuator>
    </transmission>
    <transmission name="trans_joint5">
        <type>transmission_interface/SimpleTransmission</type>
        <joint name="joint5">
            <hardwareInterface>hardware_interface/PositionJointInterface</hardwareInterface>
        </joint>
        <actuator name="joint5_motor">
            <hardwareInterface>hardware_interface/PositionJointInterface</hardwareInterface>
            <mechanicalReduction>1</mechanicalReduction>
        </actuator>
    </transmission>
    <gazebo>
        <plugin name="gazebo_ros_control">
            <robotNamespace>/</robotNamespace>
        </plugin>
    </gazebo>
</robot>

